<?xml version="1.0"?>
<robot xmlns:xacro="http://ros.org/wiki/xacro" name="linear_axis">

	<!-- Create a link for the axis -->
	<link name="axis_link_0">
		<visual>
			<origin xyz="0 0 0" rpy="0 0 0"/>
			<geometry>
				<mesh filename="package://urdf_test/meshes/AxisSimplified.stl" scale="0.001 0.001 0.001"/>
			</geometry>
			<material name="green">
				<color rgba="0.2 1 0.2 1"/>
			</material>
		</visual>
		<collision>
			<geometry>
				<mesh filename="package://urdf_test/meshes/AxisSimplified.stl" scale="0.001 0.001 0.001"/>
			</geometry>
		</collision>
		<inertial>
			<origin xyz="0 0 0" rpy="0 0 0"/>
			<mass value="128"/>
			<inertia ixx="1.0" ixy="0.0" ixz="0.0" iyy="1.0" iyz="0.0" izz="1.0"/>
		</inertial>
	</link>

	<!-- Create a joint to move the slider along the axis -->
	<joint name="axis_to_slider" type="prismatic">
		<!-- Make it start at one end of the axis -->
		<origin xyz="0.1008719 0.324412 0.8068726" rpy="0 0 0"/>
		<parent link="axis_link_0"/>
		<child link="axis_link_1"/>
		<axis xyz="1 0 0"/>
		<limit lower="0" upper="2.3" velocity="0.1" effort="100"/>
	</joint>

	<!-- Create a link for the slider -->
	<link name="axis_link_1">
		<visual>
			<origin xyz="0 0 0" rpy="0 0 0"/>
			<geometry>
				<mesh filename="package://urdf_test/meshes/Slider.stl" scale="0.001 0.001 0.001"/>
			</geometry>
			<material name="blue">
				<color rgba="0.2 0.1 1 1"/>
			</material>
		</visual>
		<collision>
			<geometry>
				<mesh filename="package://urdf_test/meshes/Slider.stl" scale="0.001 0.001 0.001"/>
			</geometry>
		</collision>
		<inertial>
			<origin xyz="0 0 0" rpy="0 0 0"/>
			<mass value="0.3"/>
			<inertia ixx="0.01" ixy="0.0" ixz="0.0" iyy="0.01" iyz="0.0" izz="0.01"/>
		</inertial>
	</link>

</robot>
